Workbook

Sheet Cover
A1: TEXAN FILLING STATION — MONTHLY CONTROL WORKBOOK
A2: Linked daily-control logs from August 2026 through August 2027
A5: SHEET | B5: PURPOSE
A6: August 2026 Log | B6: Completed source month.
A7: September 2026 Log | B7: Opening values link to August 2026.
A8: October 2026 Log | B8: Opening values link to September 2026.
A9: November 2026 Log | B9: Opening values link to October 2026.
A10: December 2026 Log | B10: Opening values link to November 2026.
A11: January 2027 Log | B11: Opening values link to December 2026.
A12: February 2027 Log | B12: Opening values link to January 2027.
A13: March 2027 Log | B13: Opening values link to February 2027.
A14: April 2027 Log | B14: Opening values link to March 2027.
A15: May 2027 Log | B15: Opening values link to April 2027.
A16: June 2027 Log | B16: Opening values link to May 2027.
... A21: SLIPS 9JUL | B21: Supporting transaction slips for 9 July.

Sheet Totals
A1: TEXAN FILLING STATION — MONTHLY TOTALS
A2: Every MONTH TOTALS line from August 2026 to August 2027; all figures are linked to the monthly logs.
A4: PERIOD 1 — AUGUST 2026 TO FEBRUARY 2027
A5: ITEM | B5: 46260 | C5: 46291 | D5: 46321 | E5: 46352 | F5: 46382 | G5: 46049 | H5: 46080 | I5: PERIOD 1 TOTAL
A6: CONTROL SUMMARY — AIRTIME DIFF | B6: =IFERROR(IF('August 2026 Log'!BO7="","",'August 2026 Log'!BO7),"") -> -96 | C6: =IFERROR(IF('September 2026 Log'!BO7="","",'September 2026 Log'!BO7),"") -> -221 | D6: =IFERROR(IF('October 2026 Log'!BO7="","",'October 2026 Log'!BO7),"") -> 0 | E6: =IFERROR(IF('November 2026 Log'!BO7="","",'November 2026 Log'!BO7),"") -> 0 | F6: =IFERROR(IF('December 2026 Log'!BO7="","",'December 2026 Log'!BO7),"") -> 0 | G6: =IFERROR(IF('January 2027 Log'!BO7="","",'January 2027 Log'!BO7),"") -> 0 | H6: =IFERROR(IF('February 2027 Log'!BO7="","",'February 2027 Log'!BO7),"") -> 0 | I6: =IF(COUNT(B6:H6)=0,"",SUM(B6:H6)) -> -317
A7: CONTROL SUMMARY — MONEY DIFF | B7: =IFERROR(IF('August 2026 Log'!BO8="","",'August 2026 Log'!BO8),"") -> 231.46 | C7: =IFERROR(IF('September 2026 Log'!BO8="","",'September 2026 Log'!BO8),"") -> 11230.96 | D7: =IFERROR(IF('October 2026 Log'!BO8="","",'October 2026 Log'!BO8),"") -> 0 | E7: =IFERROR(IF('November 2026 Log'!BO8="","",'November 2026 Log'!BO8),"") -> 0 | F7: =IFERROR(IF('December 2026 Log'!BO8="","",'December 2026 Log'!BO8),"") -> 0 | G7: =IFERROR(IF('January 2027 Log'!BO8="","",'January 2027 Log'!BO8),"") -> 0 | H7: =IFERROR(IF('February 2027 Log'!BO8="","",'February 2027 Log'!BO8),"") -> 0 | I7: =IF(COUNT(B7:H7)=0,"",SUM(B7:H7)) -> 11462.42
A8: CONTROL SUMMARY — LITRES DIFF | B8: =IFERROR(IF('August 2026 Log'!BO9="","",'August 2026 Log'!BO9),"") -> 22538 | C8: =IFERROR(IF('September 2026 Log'!BO9="","",'September 2026 Log'!BO9),"") -> -4385152 | D8: =IFERROR(IF('October 2026 Log'!BO9="","",'October 2026 Log'!BO9),"") | E8: =IFERROR(IF('November 2026 Log'!BO9="","",'November 2026 Log'!BO9),"") | F8: =IFERROR(IF('December 2026 Log'!BO9="","",'December 2026 Log'!BO9),"") | G8: =IFERROR(IF('January 2027 Log'!BO9="","",'January 2027 Log'!BO9),"") | H8: =IFERROR(IF('February 2027 Log'!BO9="","",'February 2027 Log'!BO9),"") | I8: =IF(COUNT(B8:H8)=0,"",SUM(B8:H8)) -> -4362614
A9: CONTROL SUMMARY — TOTAL LITRES | B9: =IFERROR(IF('August 2026 Log'!BO10="","",'August 2026 Log'!BO10),"") -> 50764 | C9: =IFERROR(IF('September 2026 Log'!BO10="","",'September 2026 Log'!BO10),"") -> -4342885 | D9: =IFERROR(IF('October 2026 Log'!BO10="","",'October 2026 Log'!BO10),"") | E9: =IFERROR(IF('November 2026 Log'!BO10="","",'November 2026 Log'!BO10),"") | F9: =IFERROR(IF('December 2026 Log'!BO10="","",'December 2026 Log'!BO10),"") | G9: =IFERROR(IF('January 2027 Log'!BO10="","",'January 2027 Log'!BO10),"") | H9: =IFERROR(IF('February 2027 Log'!BO10="","",'February 2027 Log'!BO10),"") | I9: =IF(COUNT(B9:H9)=0,"",SUM(B9:H9)) -> -4292121
A10: CONTROL SUMMARY — TOTAL SHOP | B10: =IFERROR(IF('August 2026 Log'!BO11="","",'August 2026 Log'!BO11),"") -> 298945.58 | C10: =IFERROR(IF('September 2026 Log'!BO11="","",'September 2026 Log'!BO11),"") -> 151964.72 | D10: =IFERROR(IF('October 2026 Log'!BO11="","",'October 2026 Log'!BO11),"") -> 0 | E10: =IFERROR(IF('November 2026 Log'!BO11="","",'November 2026 Log'!BO11),"") -> 0 | F10: =IFERROR(IF('December 2026 Log'!BO11="","",'December 2026 Log'!BO11),"") -> 0 | G10: =IFERROR(IF('January 2027 Log'!BO11="","",'January 2027 Log'!BO11),"") -> 0 | H10: =IFERROR(IF('February 2027 Log'!BO11="","",'February 2027 Log'!BO11),"") -> 0 | I10: =IF(COUNT(B10:H10)=0,"",SUM(B10:H10)) -> 450910.3
A11: CASH & AIRTIME — BONDIBLU HOLES SHELVE | B11: =IFERROR(IF('August 2026 Log'!BO17="","",'August 2026 Log'!BO17),"") -> 157 | C11: =IFERROR(IF('September 2026 Log'!BO17="","",'September 2026 Log'!BO17),"") -> 1 | D11: =IFERROR(IF('October 2026 Log'!BO17="","",'October 2026 Log'!BO17),"") | E11: =IFERROR(IF('November 2026 Log'!BO17="","",'November 2026 Log'!BO17),"") | F11: =IFERROR(IF('December 2026 Log'!BO17="","",'December 2026 Log'!BO17),"") | G11: =IFERROR(IF('January 2027 Log'!BO17="","",'January 2027 Log'!BO17),"") | H11: =IFERROR(IF('February 2027 Log'!BO17="","",'February 2027 Log'!BO17),"") | I11: =IF(COUNT(B11:H11)=0,"",SUM(B11:H11)) -> 158
A12: CASH & AIRTIME — SUNGLASSES SOLD REPORT | B12: =IFERROR(IF('August 2026 Log'!BO18="","",'August 2026 Log'!BO18),"") | C12: =IFERROR(IF('September 2026 Log'!BO18="","",'September 2026 Log'!BO18),"") | D12: =IFERROR(IF('October 2026 Log'!BO18="","",'October 2026 Log'!BO18),"") | E12: =IFERROR(IF('November 2026 Log'!BO18="","",'November 2026 Log'!BO18),"") | F12: =IFERROR(IF('December 2026 Log'!BO18="","",'December 2026 Log'!BO18),"") | G12: =IFERROR(IF('January 2027 Log'!BO18="","",'January 2027 Log'!BO18),"") | H12: =IFERROR(IF('February 2027 Log'!BO18="","",'February 2027 Log'!BO18),"") | I12: =IF(COUNT(B12:H12)=0,"",SUM(B12:H12))
A13: CASH & AIRTIME — CASH ACC | B13: =IFERROR(IF('August 2026 Log'!BO19="","",'August 2026 Log'!BO19),"") | C13: =IFERROR(IF('September 2026 Log'!BO19="","",'September 2026 Log'!BO19),"") | D13: =IFERROR(IF('October 2026 Log'!BO19="","",'October 2026 Log'!BO19),"") | E13: =IFERROR(IF('November 2026 Log'!BO19="","",'November 2026 Log'!BO19),"") | F13: =IFERROR(IF('December 2026 Log'!BO19="","",'December 2026 Log'!BO19),"") | G13: =IFERROR(IF('January 2027 Log'!BO19="","",'January 2027 Log'!BO19),"") | H13: =IFERROR(IF('February 2027 Log'!BO19="","",'February 2027 Log'!BO19),"") | I13: =IF(COUNT(B13:H13)=0,"",SUM(B13:H13))
A14: CASH & AIRTIME — COINS | B14: =IFERROR(IF('August 2026 Log'!BO20="","",'August 2026 Log'!BO20),"") | C14: =IFERROR(IF('September 2026 Log'!BO20="","",'September 2026 Log'!BO20),"") -> 11750 | D14: =IFERROR(IF('October 2026 Log'!BO20="","",'October 2026 Log'!BO20),"") | E14: =IFERROR(IF('November 2026 Log'!BO20="","",'November 2026 Log'!BO20),"") | F14: =IFERROR(IF('December 2026 Log'!BO20="","",'December 2026 Log'!BO20),"") | G14: =IFERROR(IF('January 2027 Log'!BO20="","",'January 2027 Log'!BO20),"") | H14: =IFERROR(IF('February 2027 Log'!BO20="","",'February 2027 Log'!BO20),"") | I14: =IF(COUNT(B14:H14)=0,"",SUM(B14:H14)) -> 11750
A15: CASH & AIRTIME — SAFEDROPS | B15: =IFERROR(IF('August 2026 Log'!BO21="","",'August 2026 Log'!BO21),"") -> 406880 | C15: =IFERROR(IF('September 2026 Log'!BO21="","",'September 2026 Log'!BO21),"") -> 154180 | D15: =IFERROR(IF('October 2026 Log'!BO21="","",'October 2026 Log'!BO21),"") | E15: =IFERROR(IF('November 2026 Log'!BO21="","",'November 2026 Log'!BO21),"") | F15: =IFERROR(IF('December 2026 Log'!BO21="","",'December 2026 Log'!BO21),"") | G15: =IFERROR(IF('January 2027 Log'!BO21="","",'January 2027 Log'!BO21),"") | H15: =IFERROR(IF('February 2027 Log'!BO21="","",'February 2027 Log'!BO21),"") | I15: =IF(COUNT(B15:H15)=0,"",SUM(B15:H15)) -> 561060
A16: CASH & AIRTIME — CASH | B16: =IFERROR(IF('August 2026 Log'!BO22="","",'August 2026 Log'!BO22),"") -> 406880 | C16: =IFERROR(IF('September 2026 Log'!BO22="","",'September 2026 Log'!BO22),"") -> 165930 | D16: =IFERROR(IF('October 2026 Log'!BO22="","",'October 2026 Log'!BO22),"") -> 0 | E16: =IFERROR(IF('November 2026 Log'!BO22="","",'November 2026 Log'!BO22),"") -> 0 | F16: =IFERROR(IF('December 2026 Log'!BO22="","",'December 2026 Log'!BO22),"") -> 0 | G16: =IFERROR(IF('January 2027 Log'!BO22="","",'January 2027 Log'!BO22),"") -> 0 | H16: =IFERROR(IF('February 2027 Log'!BO22="","",'February 2027 Log'!BO22),"") -> 0 | I16: =IF(COUNT(B16:H16)=0,"",SUM(B16:H16)) -> 572810
A17: CASH & AIRTIME — VOUCHERS | B17: =IFERROR(IF('August 2026 Log'!BO23="","",'August 2026 Log'!BO23),"") | C17: =IFERROR(IF('September 2026 Log'!BO23="","",'September 2026 Log'!BO23),"") | D17: =IFERROR(IF('October 2026 Log'!BO23="","",'October 2026 Log'!BO23),"") | E17: =IFERROR(IF('November 2026 Log'!BO23="","",'November 2026 Log'!BO23),"") | F17: =IFERROR(IF('December 2026 Log'!BO23="","",'December 2026 Log'!BO23),"") | G17: =IFERROR(IF('January 2027 Log'!BO23="","",'January 2027 Log'!BO23),"") | H17: =IFERROR(IF('February 2027 Log'!BO23="","",'February 2027 Log'!BO23),"") | I17: =IF(COUNT(B17:H17)=0,"",SUM(B17:H17))
A18: CASH & AIRTIME — coins banked (in minus) | B18: =IFERROR(IF('August 2026 Log'!BO24="","",'August 2026 Log'!BO24),"") | C18: =IFERROR(IF('September 2026 Log'!BO24="","",'September 2026 Log'!BO24),"") | D18: =IFERROR(IF('October 2026 Log'!BO24="","",'October 2026 Log'!BO24),"") | E18: =IFERROR(IF('November 2026 Log'!BO24="","",'November 2026 Log'!BO24),"") | F18: =IFERROR(IF('December 2026 Log'!BO24="","",'December 2026 Log'!BO24),"") | G18: =IFERROR(IF('January 2027 Log'!BO24="","",'January 2027 Log'!BO24),"") | H18: =IFERROR(IF('February 2027 Log'!BO24="","",'February 2027 Log'!BO24),"") | I18: =IF(COUNT(B18:H18)=0,"",SUM(B18:H18))
A19: CASH & AIRTIME — AIRTIME SLIP | B19: =IFERROR(IF('August 2026 Log'!BO25="","",'August 2026 Log'!BO25),"") -> 59693 | C19: =IFERROR(IF('September 2026 Log'!BO25="","",'September 2026 Log'!BO25),"") -> 23927 | D19: =IFERROR(IF('October 2026 Log'!BO25="","",'October 2026 Log'!BO25),"") | E19: =IFERROR(IF('November 2026 Log'!BO25="","",'November 2026 Log'!BO25),"") | F19: =IFERROR(IF('December 2026 Log'!BO25="","",'December 2026 Log'!BO25),"") | G19: =IFERROR(IF('January 2027 Log'!BO25="","",'January 2027 Log'!BO25),"") | H19: =IFERROR(IF('February 2027 Log'!BO25="","",'February 2027 Log'!BO25),"") | I19: =IF(COUNT(B19:H19)=0,"",SUM(B19:H19)) -> 83620
A20: CASH & AIRTIME — AIRTIME SYSTEM | B20: =IFERROR(IF('August 2026 Log'!BO26="","",'August 2026 Log'!BO26),"") -> 59597 | C20: =IFERROR(IF('September 2026 Log'!BO26="","",'September 2026 Log'!BO26),"") -> 23706 | D20: =IFERROR(IF('October 2026 Log'!BO26="","",'October 2026 Log'!BO26),"") | E20: =IFERROR(IF('November 2026 Log'!BO26="","",'November 2026 Log'!BO26),"") | F20: =IFERROR(IF('December 2026 Log'!BO26="","",'December 2026 Log'!BO26),"") | G20: =IFERROR(IF('January 2027 Log'!BO26="","",'January 2027 Log'!BO26),"") | H20: =IFERROR(IF('February 2027 Log'!BO26="","",'February 2027 Log'!BO26),"") | I20: =IF(COUNT(B20:H20)=0,"",SUM(B20:H20)) -> 83303
A21: CASH & AIRTIME — AIRTME SHIFT NR | B21: =IFERROR(IF('August 2026 Log'!BO27="","",'August 2026 Log'!BO27),"") -> 3100 | C21: =IFERROR(IF('September 2026 Log'!BO27="","",'September 2026 Log'!BO27),"") -> 1469 | D21: =IFERROR(IF('October 2026 Log'!BO27="","",'October 2026 Log'!BO27),"") | E21: =IFERROR(IF('November 2026 Log'!BO27="","",'November 2026 Log'!BO27),"") | F21: =IFERROR(IF('December 2026 Log'!BO27="","",'December 2026 Log'!BO27),"") | G21: =IFERROR(IF('January 2027 Log'!BO27="","",'January 2027 Log'!BO27),"") | H21: =IFERROR(IF('February 2027 Log'!BO27="","",'February 2027 Log'!BO27),"") | I21: =IF(COUNT(B21:H21)=0,"",SUM(B21:H21)) -> 4569
A22: CASH & AIRTIME — AIRTIME BALANCE | B22: =IFERROR(IF('August 2026 Log'!BO28="","",'August 2026 Log'!BO28),"") -> 158528.16 | C22: =IFERROR(IF('September 2026 Log'!BO28="","",'September 2026 Log'!BO28),"") -> 72143.11 | D22: =IFERROR(IF('October 2026 Log'!BO28="","",'October 2026 Log'!BO28),"") | E22: =IFERROR(IF('November 2026 Log'!BO28="","",'November 2026 Log'!BO28),"") | F22: =IFERROR(IF('December 2026 Log'!BO28="","",'December 2026 Log'!BO28),"") | G22: =IFERROR(IF('January 2027 Log'!BO28="","",'January 2027 Log'!BO28),"") | H22: =IFERROR(IF('February 2027 Log'!BO28="","",'February 2027 Log'!BO28),"") | I22: =IF(COUNT(B22:H22)=0,"",SUM(B22:H22)) -> 230671.27
... A53: CARDS & SALES — AIRTIME DIFF | B53: =IFERROR(IF('August 2026 Log'!BO59="","",'August 2026 Log'!BO59),"") -> -96 | C53: =IFERROR(IF('September 2026 Log'!BO59="","",'September 2026 Log'!BO59),"") -> -221 | D53: =IFERROR(IF('October 2026 Log'!BO59="","",'October 2026 Log'!BO59),"") -> 0 | E53: =IFERROR(IF('November 2026 Log'!BO59="","",'November 2026 Log'!BO59),"") -> 0 | F53: =IFERROR(IF('December 2026 Log'!BO59="","",'December 2026 Log'!BO59),"") -> 0 | G53: =IFERROR(IF('January 2027 Log'!BO59="","",'January 2027 Log'!BO59),"") -> 0 | H53: =IFERROR(IF('February 2027 Log'!BO59="","",'February 2027 Log'!BO59),"") -> 0 | I53: =IF(COUNT(B53:H53)=0,"",SUM(B53:H53)) -> -317
A54: FUEL DIPS & SALES — differences DIPS | B54: =IFERROR(IF('August 2026 Log'!BO61="","",'August 2026 Log'!BO61),"") -> 22538 | C54: =IFERROR(IF('September 2026 Log'!BO61="","",'September 2026 Log'!BO61),"") -> -4385152 | D54: =IFERROR(IF('October 2026 Log'!BO61="","",'October 2026 Log'!BO61),"") | E54: =IFERROR(IF('November 2026 Log'!BO61="","",'November 2026 Log'!BO61),"") | F54: =IFERROR(IF('December 2026 Log'!BO61="","",'December 2026 Log'!BO61),"") | G54: =IFERROR(IF('January 2027 Log'!BO61="","",'January 2027 Log'!BO61),"") | H54: =IFERROR(IF('February 2027 Log'!BO61="","",'February 2027 Log'!BO61),"") | I54: =IF(COUNT(B54:H54)=0,"",SUM(B54:H54)) -> -4362614
A55: FUEL DIPS & SALES — DIPS ULP95 | B55: =IFERROR(IF('August 2026 Log'!BO62="","",'August 2026 Log'!BO62),"") -> 2855 | C55: =IFERROR(IF('September 2026 Log'!BO62="","",'September 2026 Log'!BO62),"") -> 16500 | D55: =IFERROR(IF('October 2026 Log'!BO62="","",'October 2026 Log'!BO62),"") | E55: =IFERROR(IF('November 2026 Log'!BO62="","",'November 2026 Log'!BO62),"") | F55: =IFERROR(IF('December 2026 Log'!BO62="","",'December 2026 Log'!BO62),"") | G55: =IFERROR(IF('January 2027 Log'!BO62="","",'January 2027 Log'!BO62),"") | H55: =IFERROR(IF('February 2027 Log'!BO62="","",'February 2027 Log'!BO62),"") | I55: =IF(COUNT(B55:H55)=0,"",SUM(B55:H55)) -> 19355
A56: FUEL DIPS & SALES — DIPS ULP93 | B56: =IFERROR(IF('August 2026 Log'!BO63="","",'August 2026 Log'!BO63),"") -> 1831 | C56: =IFERROR(IF('September 2026 Log'!BO63="","",'September 2026 Log'!BO63),"") -> 3400 | D56: =IFERROR(IF('October 2026 Log'!BO63="","",'October 2026 Log'!BO63),"") | E56: =IFERROR(IF('November 2026 Log'!BO63="","",'November 2026 Log'!BO63),"") | F56: =IFERROR(IF('December 2026 Log'!BO63="","",'December 2026 Log'!BO63),"") | G56: =IFERROR(IF('January 2027 Log'!BO63="","",'January 2027 Log'!BO63),"") | H56: =IFERROR(IF('February 2027 Log'!BO63="","",'February 2027 Log'!BO63),"") | I56: =IF(COUNT(B56:H56)=0,"",SUM(B56:H56)) -> 5231
A57: FUEL DIPS & SALES — DIPS ULP93 | B57: =IFERROR(IF('August 2026 Log'!BO64="","",'August 2026 Log'!BO64),"") -> 2012 | C57: =IFERROR(IF('September 2026 Log'!BO64="","",'September 2026 Log'!BO64),"") -> 2600 | D57: =IFERROR(IF('October 2026 Log'!BO64="","",'October 2026 Log'!BO64),"") | E57: =IFERROR(IF('November 2026 Log'!BO64="","",'November 2026 Log'!BO64),"") | F57: =IFERROR(IF('December 2026 Log'!BO64="","",'December 2026 Log'!BO64),"") | G57: =IFERROR(IF('January 2027 Log'!BO64="","",'January 2027 Log'!BO64),"") | H57: =IFERROR(IF('February 2027 Log'!BO64="","",'February 2027 Log'!BO64),"") | I57: =IF(COUNT(B57:H57)=0,"",SUM(B57:H57)) -> 4612
A58: FUEL DIPS & SALES — DIPS D50 | B58: =IFERROR(IF('August 2026 Log'!BO65="","",'August 2026 Log'!BO65),"") -> 11302 | C58: =IFERROR(IF('September 2026 Log'!BO65="","",'September 2026 Log'!BO65),"") -> 9597 | D58: =IFERROR(IF('October 2026 Log'!BO65="","",'October 2026 Log'!BO65),"") | E58: =IFERROR(IF('November 2026 Log'!BO65="","",'November 2026 Log'!BO65),"") | F58: =IFERROR(IF('December 2026 Log'!BO65="","",'December 2026 Log'!BO65),"") | G58: =IFERROR(IF('January 2027 Log'!BO65="","",'January 2027 Log'!BO65),"") | H58: =IFERROR(IF('February 2027 Log'!BO65="","",'February 2027 Log'!BO65),"") | I58: =IF(COUNT(B58:H58)=0,"",SUM(B58:H58)) -> 20899
A59: FUEL DIPS & SALES — DIPS D50 | B59: =IFERROR(IF('August 2026 Log'!BO66="","",'August 2026 Log'!BO66),"") -> 10226 | C59: =IFERROR(IF('September 2026 Log'!BO66="","",'September 2026 Log'!BO66),"") -> 10170 | D59: =IFERROR(IF('October 2026 Log'!BO66="","",'October 2026 Log'!BO66),"") | E59: =IFERROR(IF('November 2026 Log'!BO66="","",'November 2026 Log'!BO66),"") | F59: =IFERROR(IF('December 2026 Log'!BO66="","",'December 2026 Log'!BO66),"") | G59: =IFERROR(IF('January 2027 Log'!BO66="","",'January 2027 Log'!BO66),"") | H59: =IFERROR(IF('February 2027 Log'!BO66="","",'February 2027 Log'!BO66),"") | I59: =IF(COUNT(B59:H59)=0,"",SUM(B59:H59)) -> 20396
A60: FUEL DIPS & SALES — Unlabeled total (source row 67) | B60: =IFERROR(IF('August 2026 Log'!BO67="","",'August 2026 Log'!BO67),"") -> 18584.38 | C60: =IFERROR(IF('September 2026 Log'!BO67="","",'September 2026 Log'!BO67),"") -> -7246958.3 | D60: =IFERROR(IF('October 2026 Log'!BO67="","",'October 2026 Log'!BO67),"") | E60: =IFERROR(IF('November 2026 Log'!BO67="","",'November 2026 Log'!BO67),"") | F60: =IFERROR(IF('December 2026 Log'!BO67="","",'December 2026 Log'!BO67),"") | G60: =IFERROR(IF('January 2027 Log'!BO67="","",'January 2027 Log'!BO67),"") | H60: =IFERROR(IF('February 2027 Log'!BO67="","",'February 2027 Log'!BO67),"") | I60: =IF(COUNT(B60:H60)=0,"",SUM(B60:H60)) -> -7228373.9
A61: FUEL DIPS & SALES — SALES D50 T4 PUMP1/4 | B61: =IFERROR(IF('August 2026 Log'!BO68="","",'August 2026 Log'!BO68),"") -> 12413 | C61: =IFERROR(IF('September 2026 Log'!BO68="","",'September 2026 Log'!BO68),"") -> -1022725 | D61: =IFERROR(IF('October 2026 Log'!BO68="","",'October 2026 Log'!BO68),"") | E61: =IFERROR(IF('November 2026 Log'!BO68="","",'November 2026 Log'!BO68),"") | F61: =IFERROR(IF('December 2026 Log'!BO68="","",'December 2026 Log'!BO68),"") | G61: =IFERROR(IF('January 2027 Log'!BO68="","",'January 2027 Log'!BO68),"") | H61: =IFERROR(IF('February 2027 Log'!BO68="","",'February 2027 Log'!BO68),"") | I61: =IF(COUNT(B61:H61)=0,"",SUM(B61:H61)) -> -1010312
A62: FUEL DIPS & SALES — SALES D50 T5 PUMP 9/12 | B62: =IFERROR(IF('August 2026 Log'!BO69="","",'August 2026 Log'!BO69),"") -> 12255 | C62: =IFERROR(IF('September 2026 Log'!BO69="","",'September 2026 Log'!BO69),"") -> -121458 | D62: =IFERROR(IF('October 2026 Log'!BO69="","",'October 2026 Log'!BO69),"") | E62: =IFERROR(IF('November 2026 Log'!BO69="","",'November 2026 Log'!BO69),"") | F62: =IFERROR(IF('December 2026 Log'!BO69="","",'December 2026 Log'!BO69),"") | G62: =IFERROR(IF('January 2027 Log'!BO69="","",'January 2027 Log'!BO69),"") | H62: =IFERROR(IF('February 2027 Log'!BO69="","",'February 2027 Log'!BO69),"") | I62: =IF(COUNT(B62:H62)=0,"",SUM(B62:H62)) -> -109203
A63: FUEL DIPS & SALES — SALES ULP93 T2 PUMP3/6 | B63: =IFERROR(IF('August 2026 Log'!BO70="","",'August 2026 Log'!BO70),"") -> 4688 | C63: =IFERROR(IF('September 2026 Log'!BO70="","",'September 2026 Log'!BO70),"") -> -1571126 | D63: =IFERROR(IF('October 2026 Log'!BO70="","",'October 2026 Log'!BO70),"") | E63: =IFERROR(IF('November 2026 Log'!BO70="","",'November 2026 Log'!BO70),"") | F63: =IFERROR(IF('December 2026 Log'!BO70="","",'December 2026 Log'!BO70),"") | G63: =IFERROR(IF('January 2027 Log'!BO70="","",'January 2027 Log'!BO70),"") | H63: =IFERROR(IF('February 2027 Log'!BO70="","",'February 2027 Log'!BO70),"") | I63: =IF(COUNT(B63:H63)=0,"",SUM(B63:H63)) -> -1566438
A64: FUEL DIPS & SALES — SALES ULP93 T3 PUMP7/10 | B64: =IFERROR(IF('August 2026 Log'!BO71="","",'August 2026 Log'!BO71),"") -> 3841 | C64: =IFERROR(IF('September 2026 Log'!BO71="","",'September 2026 Log'!BO71),"") -> -69673 | D64: =IFERROR(IF('October 2026 Log'!BO71="","",'October 2026 Log'!BO71),"") | E64: =IFERROR(IF('November 2026 Log'!BO71="","",'November 2026 Log'!BO71),"") | F64: =IFERROR(IF('December 2026 Log'!BO71="","",'December 2026 Log'!BO71),"") | G64: =IFERROR(IF('January 2027 Log'!BO71="","",'January 2027 Log'!BO71),"") | H64: =IFERROR(IF('February 2027 Log'!BO71="","",'February 2027 Log'!BO71),"") | I64: =IF(COUNT(B64:H64)=0,"",SUM(B64:H64)) -> -65832
A65: FUEL DIPS & SALES — SALES ULP95 T1 PUMP 2/5/8/11 | B65: =IFERROR(IF('August 2026 Log'!BO72="","",'August 2026 Log'!BO72),"") -> 17567 | C65: =IFERROR(IF('September 2026 Log'!BO72="","",'September 2026 Log'!BO72),"") -> -1557903 | D65: =IFERROR(IF('October 2026 Log'!BO72="","",'October 2026 Log'!BO72),"") | E65: =IFERROR(IF('November 2026 Log'!BO72="","",'November 2026 Log'!BO72),"") | F65: =IFERROR(IF('December 2026 Log'!BO72="","",'December 2026 Log'!BO72),"") | G65: =IFERROR(IF('January 2027 Log'!BO72="","",'January 2027 Log'!BO72),"") | H65: =IFERROR(IF('February 2027 Log'!BO72="","",'February 2027 Log'!BO72),"") | I65: =IF(COUNT(B65:H65)=0,"",SUM(B65:H65)) -> -1540336
... A68: FUEL DIPS & SALES — SHOP SALES AMOUNT | B68: =IFERROR(IF('August 2026 Log'!BO75="","",'August 2026 Log'!BO75),"") -> 299898.28 | C68: =IFERROR(IF('September 2026 Log'!BO75="","",'September 2026 Log'!BO75),"") -> 152282.67 | D68: =IFERROR(IF('October 2026 Log'!BO75="","",'October 2026 Log'!BO75),"") -> 0 | E68: =IFERROR(IF('November 2026 Log'!BO75="","",'November 2026 Log'!BO75),"") -> 0 | F68: =IFERROR(IF('December 2026 Log'!BO75="","",'December 2026 Log'!BO75),"") -> 0 | G68: =IFERROR(IF('January 2027 Log'!BO75="","",'January 2027 Log'!BO75),"") -> 0 | H68: =IFERROR(IF('February 2027 Log'!BO75="","",'February 2027 Log'!BO75),"") -> 0 | I68: =IF(COUNT(B68:H68)=0,"",SUM(B68:H68)) -> 452180.95
A69: MECHANICAL — N1 D50 T4 | B69: =IFERROR(IF('August 2026 Log'!BO77="","",'August 2026 Log'!BO77),"") -> 5479 | C69: =IFERROR(IF('September 2026 Log'!BO77="","",'September 2026 Log'!BO77),"") -> -999570 | D69: =IFERROR(IF('October 2026 Log'!BO77="","",'October 2026 Log'!BO77),"") | E69: =IFERROR(IF('November 2026 Log'!BO77="","",'November 2026 Log'!BO77),"") | F69: =IFERROR(IF('December 2026 Log'!BO77="","",'December 2026 Log'!BO77),"") | G69: =IFERROR(IF('January 2027 Log'!BO77="","",'January 2027 Log'!BO77),"") | H69: =IFERROR(IF('February 2027 Log'!BO77="","",'February 2027 Log'!BO77),"") | I69: =IF(COUNT(B69:H69)=0,"",SUM(B69:H69)) -> -994091
A70: MECHANICAL — N2 ULP95 T1 | B70: =IFERROR(IF('August 2026 Log'!BO78="","",'August 2026 Log'!BO78),"") -> 3398 | C70: =IFERROR(IF('September 2026 Log'!BO78="","",'September 2026 Log'!BO78),"") -> -719342 | D70: =IFERROR(IF('October 2026 Log'!BO78="","",'October 2026 Log'!BO78),"") | E70: =IFERROR(IF('November 2026 Log'!BO78="","",'November 2026 Log'!BO78),"") | F70: =IFERROR(IF('December 2026 Log'!BO78="","",'December 2026 Log'!BO78),"") | G70: =IFERROR(IF('January 2027 Log'!BO78="","",'January 2027 Log'!BO78),"") | H70: =IFERROR(IF('February 2027 Log'!BO78="","",'February 2027 Log'!BO78),"") | I70: =IF(COUNT(B70:H70)=0,"",SUM(B70:H70)) -> -715944
A71: MECHANICAL — N3 ULP93 T2 | B71: =IFERROR(IF('August 2026 Log'!BO79="","",'August 2026 Log'!BO79),"") -> 2433 | C71: =IFERROR(IF('September 2026 Log'!BO79="","",'September 2026 Log'!BO79),"") -> -831599 | D71: =IFERROR(IF('October 2026 Log'!BO79="","",'October 2026 Log'!BO79),"") | E71: =IFERROR(IF('November 2026 Log'!BO79="","",'November 2026 Log'!BO79),"") | F71: =IFERROR(IF('December 2026 Log'!BO79="","",'December 2026 Log'!BO79),"") | G71: =IFERROR(IF('January 2027 Log'!BO79="","",'January 2027 Log'!BO79),"") | H71: =IFERROR(IF('February 2027 Log'!BO79="","",'February 2027 Log'!BO79),"") | I71: =IF(COUNT(B71:H71)=0,"",SUM(B71:H71)) -> -829166
A72: MECHANICAL — N4 D50 T4 | B72: =IFERROR(IF('August 2026 Log'!BO80="","",'August 2026 Log'!BO80),"") -> 6934 | C72: =IFERROR(IF('September 2026 Log'!BO80="","",'September 2026 Log'!BO80),"") -> -23155 | D72: =IFERROR(IF('October 2026 Log'!BO80="","",'October 2026 Log'!BO80),"") | E72: =IFERROR(IF('November 2026 Log'!BO80="","",'November 2026 Log'!BO80),"") | F72: =IFERROR(IF('December 2026 Log'!BO80="","",'December 2026 Log'!BO80),"") | G72: =IFERROR(IF('January 2027 Log'!BO80="","",'January 2027 Log'!BO80),"") | H72: =IFERROR(IF('February 2027 Log'!BO80="","",'February 2027 Log'!BO80),"") | I72: =IF(COUNT(B72:H72)=0,"",SUM(B72:H72)) -> -16221
A73: MECHANICAL — N5 ULP95 T1 | B73: =IFERROR(IF('August 2026 Log'!BO81="","",'August 2026 Log'!BO81),"") -> 5436 | C73: =IFERROR(IF('September 2026 Log'!BO81="","",'September 2026 Log'!BO81),"") -> -742645 | D73: =IFERROR(IF('October 2026 Log'!BO81="","",'October 2026 Log'!BO81),"") | E73: =IFERROR(IF('November 2026 Log'!BO81="","",'November 2026 Log'!BO81),"") | F73: =IFERROR(IF('December 2026 Log'!BO81="","",'December 2026 Log'!BO81),"") | G73: =IFERROR(IF('January 2027 Log'!BO81="","",'January 2027 Log'!BO81),"") | H73: =IFERROR(IF('February 2027 Log'!BO81="","",'February 2027 Log'!BO81),"") | I73: =IF(COUNT(B73:H73)=0,"",SUM(B73:H73)) -> -737209
...

Sheet August 2026 Log
A1: ="TEXAN FILLING STATION — "&UPPER(TEXT(B3,"MMMM YYYY"))&" DAILY CONTROL" -> TEXAN FILLING STATION — AUGUST 2026 DAILY CONTROL
A2: Select the month in B3. Yellow cells are manual entries; blue cells calculate automatically; negative calculated values are flagged red.
A3: MONTH | B3: 46235 | C3: OPENING / MANUAL | D3: MANUAL INPUT | E3: CALCULATED | F3: NEGATIVE CALC
A5: =68*0.1 -> 6.8 | C5: OPENING READINGS | D5: =IF(D6="","",UPPER(TEXT(D6,"dddd"))) -> SATURDAY | F5: =IF(F6="","",UPPER(TEXT(F6,"dddd"))) -> SUNDAY | H5: =IF(H6="","",UPPER(TEXT(H6,"dddd"))) -> MONDAY | J5: =IF(J6="","",UPPER(TEXT(J6,"dddd"))) -> TUESDAY | L5: =IF(L6="","",UPPER(TEXT(L6,"dddd"))) -> WEDNESDAY | N5: =IF(N6="","",UPPER(TEXT(N6,"dddd"))) -> THURSDAY | P5: =IF(P6="","",UPPER(TEXT(P6,"dddd"))) -> FRIDAY | R5: =IF(R6="","",UPPER(TEXT(R6,"dddd"))) -> SATURDAY | T5: =IF(T6="","",UPPER(TEXT(T6,"dddd"))) -> SUNDAY | V5: =IF(V6="","",UPPER(TEXT(V6,"dddd"))) -> MONDAY | X5: =IF(X6="","",UPPER(TEXT(X6,"dddd"))) -> TUESDAY | Z5: =IF(Z6="","",UPPER(TEXT(Z6,"dddd"))) -> WEDNESDAY | AB5: =IF(AB6="","",UPPER(TEXT(AB6,"dddd"))) -> THURSDAY | AD5: =IF(AD6="","",UPPER(TEXT(AD6,"dddd"))) -> FRIDAY | AF5: =IF(AF6="","",UPPER(TEXT(AF6,"dddd"))) -> SATURDAY | AH5: =IF(AH6="","",UPPER(TEXT(AH6,"dddd"))) -> SUNDAY | AJ5: =IF(AJ6="","",UPPER(TEXT(AJ6,"dddd"))) -> MONDAY | AL5: =IF(AL6="","",UPPER(TEXT(AL6,"dddd"))) -> TUESDAY | AN5: =IF(AN6="","",UPPER(TEXT(AN6,"dddd"))) -> WEDNESDAY | AP5: =IF(AP6="","",UPPER(TEXT(AP6,"dddd"))) -> THURSDAY | AR5: =IF(AR6="","",UPPER(TEXT(AR6,"dddd"))) -> FRIDAY | AT5: =IF(AT6="","",UPPER(TEXT(AT6,"dddd"))) -> SATURDAY | AV5: =IF(AV6="","",UPPER(TEXT(AV6,"dddd"))) -> SUNDAY | AX5: =IF(AX6="","",UPPER(TEXT(AX6,"dddd"))) -> MONDAY | AZ5: =IF(AZ6="","",UPPER(TEXT(AZ6,"dddd"))) -> TUESDAY | BB5: =IF(BB6="","",UPPER(TEXT(BB6,"dddd"))) -> WEDNESDAY | BD5: =IF(BD6="","",UPPER(TEXT(BD6,"dddd"))) -> THURSDAY | BF5: =IF(BF6="","",UPPER(TEXT(BF6,"dddd"))) -> FRIDAY | BH5: =IF(BH6="","",UPPER(TEXT(BH6,"dddd"))) -> SATURDAY | BJ5: =IF(BJ6="","",UPPER(TEXT(BJ6,"dddd"))) -> SUNDAY | BL5: =IF(BL6="","",UPPER(TEXT(BL6,"dddd"))) -> MONDAY | BN5: MONTH TOTALS | BP5: NEXT MONTH OPENING
C6: FROM PREVIOUS MONTH | D6: =IF($B$3="","",IF(MONTH($B$3+0)=MONTH($B$3),$B$3+0,"")) -> 46235 | F6: =IF($B$3="","",IF(MONTH($B$3+1)=MONTH($B$3),$B$3+1,"")) -> 46236 | H6: =IF($B$3="","",IF(MONTH($B$3+2)=MONTH($B$3),$B$3+2,"")) -> 46237 | J6: =IF($B$3="","",IF(MONTH($B$3+3)=MONTH($B$3),$B$3+3,"")) -> 46238 | L6: =IF($B$3="","",IF(MONTH($B$3+4)=MONTH($B$3),$B$3+4,"")) -> 46239 | N6: =IF($B$3="","",IF(MONTH($B$3+5)=MONTH($B$3),$B$3+5,"")) -> 46240 | P6: =IF($B$3="","",IF(MONTH($B$3+6)=MONTH($B$3),$B$3+6,"")) -> 46241 | R6: =IF($B$3="","",IF(MONTH($B$3+7)=MONTH($B$3),$B$3+7,"")) -> 46242 | T6: =IF($B$3="","",IF(MONTH($B$3+8)=MONTH($B$3),$B$3+8,"")) -> 46243 | V6: =IF($B$3="","",IF(MONTH($B$3+9)=MONTH($B$3),$B$3+9,"")) -> 46244 | X6: =IF($B$3="","",IF(MONTH($B$3+10)=MONTH($B$3),$B$3+10,"")) -> 46245 | Z6: =IF($B$3="","",IF(MONTH($B$3+11)=MONTH($B$3),$B$3+11,"")) -> 46246 | AB6: =IF($B$3="","",IF(MONTH($B$3+12)=MONTH($B$3),$B$3+12,"")) -> 46247 | AD6: =IF($B$3="","",IF(MONTH($B$3+13)=MONTH($B$3),$B$3+13,"")) -> 46248 | AF6: =IF($B$3="","",IF(MONTH($B$3+14)=MONTH($B$3),$B$3+14,"")) -> 46249 | AH6: =IF($B$3="","",IF(MONTH($B$3+15)=MONTH($B$3),$B$3+15,"")) -> 46250 | AJ6: =IF($B$3="","",IF(MONTH($B$3+16)=MONTH($B$3),$B$3+16,"")) -> 46251 | AL6: =IF($B$3="","",IF(MONTH($B$3+17)=MONTH($B$3),$B$3+17,"")) -> 46252 | AN6: =IF($B$3="","",IF(MONTH($B$3+18)=MONTH($B$3),$B$3+18,"")) -> 46253 | AP6: =IF($B$3="","",IF(MONTH($B$3+19)=MONTH($B$3),$B$3+19,"")) -> 46254 | AR6: =IF($B$3="","",IF(MONTH($B$3+20)=MONTH($B$3),$B$3+20,"")) -> 46255 | AT6: =IF($B$3="","",IF(MONTH($B$3+21)=MONTH($B$3),$B$3+21,"")) -> 46256 | AV6: =IF($B$3="","",IF(MONTH($B$3+22)=MONTH($B$3),$B$3+22,"")) -> 46257 | AX6: =IF($B$3="","",IF(MONTH($B$3+23)=MONTH($B$3),$B$3+23,"")) -> 46258 | AZ6: =IF($B$3="","",IF(MONTH($B$3+24)=MONTH($B$3),$B$3+24,"")) -> 46259 | BB6: =IF($B$3="","",IF(MONTH($B$3+25)=MONTH($B$3),$B$3+25,"")) -> 46260 | BD6: =IF($B$3="","",IF(MONTH($B$3+26)=MONTH($B$3),$B$3+26,"")) -> 46261 | BF6: =IF($B$3="","",IF(MONTH($B$3+27)=MONTH($B$3),$B$3+27,"")) -> 46262 | BH6: =IF($B$3="","",IF(MONTH($B$3+28)=MONTH($B$3),$B$3+28,"")) -> 46263 | BJ6: =IF($B$3="","",IF(MONTH($B$3+29)=MONTH($B$3),$B$3+29,"")) -> 46264 | BL6: =IF($B$3="","",IF(MONTH($B$3+30)=MONTH($B$3),$B$3+30,"")) -> 46265 | BN6: AFTER DAY 31 | BP6: =IF($B$3="","",EOMONTH($B$3,0)+1) -> 46266
A7: AIRTIME DIFF | E7: =E59 -> 0 | G7: =G59 -> 4 | I7: =I59 -> 0 | K7: =K59 -> 0 | M7: =M59 -> 10 | O7: =O59 -> 0 | Q7: =Q59 -> 0 | S7: =S59 -> 0 | U7: =U59 -> 0 | W7: =W59 -> 0 | Y7: =Y59 -> 0 | AA7: =AA59 -> 0 | AC7: =AC59 -> 0 | AE7: =AE59 -> 0 | AG7: =AG59 -> 0 | AI7: =AI59 -> 0 | AK7: =AK59 -> 0 | AM7: =AM59 -> 0 | AO7: =AO59 -> 0 | AQ7: =AQ59 -> -30 | AS7: =AS59 -> 0 | AU7: =AU59 -> 0 | AW7: =AW59 -> 0 | AY7: =AY59 -> 0 | BA7: =BA59 -> 0 | BC7: =BC59 -> 0 | BE7: =BE59 -> 0 | BG7: =BG59 -> -80 | BI7: =BI59 -> 0 | BK7: =BK59 -> 0 | BM7: =BM59 -> 0 | BO7: =IF(COUNT(E7,G7,I7,K7,M7,O7,Q7,S7,U7,W7,Y7,AA7,AC7,AE7,AG7,AI7,AK7,AM7,AO7,AQ7,AS7,AU7,AW7,AY7,BA7,BC7,BE7,BG7,BI7,BK7,BM7)=0,"",SUM(E7,G7,I7,K7,M7,O7,Q7,S7,U7,W7,Y7,AA7,AC7,AE7,AG7,AI7,AK7,AM7,AO7,AQ7,AS7,AU7,AW7,AY7,BA7,BC7,BE7,BG7,BI7,BK7,BM7)) -> -96 | BQ7: =BQ59 -> 0
A8: MONEY DIFF | E8: =E58 -> 20.12 | G8: =G58 -> -2.23 | I8: =I58 -> 49.54 | K8: =K58 -> 31.7 | M8: =M58 -> -843.81 | O8: =O58 -> 858.51 | Q8: =Q58 -> 84.56 | S8: =S58 -> 4.81 | U8: =U58 -> -106.99 | W8: =W58 -> 145.34 | Y8: =Y58 -> 47.72 | AA8: =AA58 -> -15.19 | AC8: =AC58 -> -123.28 | AE8: =AE58 -> -9.66 | AG8: =AG58 -> -7.94 | AI8: =AI58 -> -3.37 | AK8: =AK58 -> -97.02 | AM8: =AM58 -> -178.64 | AO8: =AO58 -> 21.05 | AQ8: =AQ58 -> -122.6 | AS8: =AS58 -> 476.07 | AU8: =AU58 -> -248.31 | AW8: =AW58 -> 10.56 | AY8: =AY58 -> 9.23 | BA8: =BA58 -> 162.24 | BC8: =BC58 -> -24.84 | BE8: =BE58 -> 14 | BG8: =BG58 -> 55.09 | BI8: =BI58 -> -18.7 | BK8: =BK58 -> 27.2 | BM8: =BM58 -> 16.3 | BO8: =IF(COUNT(E8,G8,I8,K8,M8,O8,Q8,S8,U8,W8,Y8,AA8,AC8,AE8,AG8,AI8,AK8,AM8,AO8,AQ8,AS8,AU8,AW8,AY8,BA8,BC8,BE8,BG8,BI8,BK8,BM8)=0,"",SUM(E8,G8,I8,K8,M8,O8,Q8,S8,U8,W8,Y8,AA8,AC8,AE8,AG8,AI8,AK8,AM8,AO8,AQ8,AS8,AU8,AW8,AY8,BA8,BC8,BE8,BG8,BI8,BK8,BM8)) -> 231.46 | BQ8: =BQ58 -> 51.76
A9: LITRES DIFF | E9: =E61 -> 82 | G9: =G61 -> -20 | I9: =I61 -> 142 | K9: =K61 -> -562 | M9: =M61 -> 660 | O9: =O61 -> -695 | Q9: =Q61 -> -210 | S9: =S61 -> -140 | U9: =U61 -> -220 | W9: =W61 -> -114 | Y9: =Y61 -> -404 | AA9: =AA61 -> 81 | AC9: =AC61 -> -490 | AE9: =AE61 -> -132 | AG9: =AG61 -> -167 | AI9: =AI61 -> 62 | AK9: =AK61 -> 252 | AM9: =AM61 -> 34 | AO9: =AO61 -> -254 | AQ9: =AQ61 -> -57 | AS9: =AS61 -> 97 | AU9: =AU61 -> -403 | AW9: =AW61 -> -238 | AY9: =AY61 -> 400 | BA9: =BA61 -> -78 | BC9: =BC61 -> 3780 | BE9: =BE61 -> 203 | BG9: =BG61 -> -280 | BI9: =BI61 -> 21841 | BK9: =BK61 -> -492 | BM9: =BM61 -> -140 | BO9: =IF(COUNT(E9,G9,I9,K9,M9,O9,Q9,S9,U9,W9,Y9,AA9,AC9,AE9,AG9,AI9,AK9,AM9,AO9,AQ9,AS9,AU9,AW9,AY9,BA9,BC9,BE9,BG9,BI9,BK9,BM9)=0,"",SUM(E9,G9,I9,K9,M9,O9,Q9,S9,U9,W9,Y9,AA9,AC9,AE9,AG9,AI9,AK9,AM9,AO9,AQ9,AS9,AU9,AW9,AY9,BA9,BC9,BE9,BG9,BI9,BK9,BM9)) -> 22538 | BQ9: =BQ61 -> -1002160
A10: TOTAL LITRES | C10: 1413.73 | E10: =E73 -> 1882 | G10: =G73 -> 1086 | I10: =I73 -> 2242 | K10: =K73 -> 2038 | M10: =M73 -> 1960 | O10: =O73 -> 1505 | Q10: =Q73 -> 1593 | S10: =S73 -> 1460 | U10: =U73 -> 980 | W10: =W73 -> 1386 | Y10: =Y73 -> 1649 | AA10: =AA73 -> 1581 | AC10: =AC73 -> 1710 | AE10: =AE73 -> 1932 | AG10: =AG73 -> 1233 | AI10: =AI73 -> 962 | AK10: =AK73 -> 1852 | AM10: =AM73 -> 1634 | AO10: =AO73 -> 1746 | AQ10: =AQ73 -> 1543 | AS10: =AS73 -> 1997 | AU10: =AU73 -> 1597 | AW10: =AW73 -> 962 | AY10: =AY73 -> 1400 | BA10: =BA73 -> 2122 | BC10: =BC73 -> 1480 | BE10: =BE73 -> 2203 | BG10: =BG73 -> 2220 | BI10: =BI73 -> 1641 | BK10: =BK73 -> 1108 | BM10: =BM73 -> 2060 | BO10: =IF(COUNT(E10,G10,I10,K10,M10,O10,Q10,S10,U10,W10,Y10,AA10,AC10,AE10,AG10,AI10,AK10,AM10,AO10,AQ10,AS10,AU10,AW10,AY10,BA10,BC10,BE10,BG10,BI10,BK10,BM10)=0,"",SUM(E10,G10,I10,K10,M10,O10,Q10,S10,U10,W10,Y10,AA10,AC10,AE10,AG10,AI10,AK10,AM10,AO10,AQ10,AS10,AU10,AW10,AY10,BA10,BC10,BE10,BG10,BI10,BK10,BM10)) -> 50764 | BQ10: =BQ73 -> -996093
A11: TOTAL SHOP | C11: 5252.8 | E11: =E75+E56 -> 9645.96 | G11: =G75+G56 -> 6603.86 | I11: =I75+I56 -> 9571.44 | K11: =K75+K56 -> 10754.27 | M11: =M75+M56 -> 9218.12 | O11: =O75+O56 -> 9612.04 | Q11: =Q75+Q56 -> 11923.71 | S11: =S75+S56 -> 11713 | U11: =U75+U56 -> 7473.71 | W11: =W75+W56 -> 8811.01 | X11: =X75 -> 0 | Y11: =Y75+Y56 -> 7032.97 | Z11: =Z75 -> 0 | AA11: =AA75+AA56 -> 8641.14 | AB11: =AB75 -> 0 | AC11: =AC75+AC56 -> 9935.51 | AD11: =AD75 -> 0 | AE11: =AE75+AE56 -> 10252.26 | AF11: =AF75 -> 0 | AG11: =AG75+AG56 -> 9509.56 | AH11: =AH75 -> 0 | AI11: =AI75+AI56 -> 5819.76 | AJ11: =AJ75 -> 0 | AK11: =AK75+AK56 -> 9362.85 | AL11: =AL75 -> 0 | AM11: =AM75+AM56 -> 9144.18 | AO11: =AO75+AO56 -> 9293.77 | AQ11: =AQ75+AQ56 -> 9483.13 | AS11: =AS75+AS56 -> 11446.47 | AU11: =AU75+AU56 -> 10229.47 | AW11: =AW75+AW56 -> 7999.54 | AY11: =AY75+AY56 -> 8612.87 | BA11: =BA75+BA56 -> 8497.44 | BC11: =BC75+BC56 -> 9634.96 | BE11: =BE75+BE56 -> 10238.47 | BG11: =BG75+BG56 -> 14529.26 | BI11: =BI75+BI56 -> 10343 | BK11: =BK75+BK56 -> 9654 | BM11: =BM75+BM56 -> 13957.85 | BO11: =IF(COUNT(E11,G11,I11,K11,M11,O11,Q11,S11,U11,W11,Y11,AA11,AC11,AE11,AG11,AI11,AK11,AM11,AO11,AQ11,AS11,AU11,AW11,AY11,BA11,BC11,BE11,BG11,BI11,BK11,BM11)=0,"",SUM(E11,G11,I11,K11,M11,O11,Q11,S11,U11,W11,Y11,AA11,AC11,AE11,AG11,AI11,AK11,AM11,AO11,AQ11,AS11,AU11,AW11,AY11,BA11,BC11,BE11,BG11,BI11,BK11,BM11)) -> 298945.58 | BQ11: =BQ75+BQ56 -> 10405.21
A13: TIME: | C13: 0.79166667 | D13: TIME | E13: 0.79166667 | F13: TIME | G13: 0.79166667 | H13: TIME | I13: 0.79166667 | J13: TIME | K13: 0.79166667 | L13: TIME | M13: 0.79166667 | N13: TIME | O13: 0.79166667 | P13: TIME | Q13: 0.79166667 | R13: TIME | S13: 0.79166667 | T13: TIME | U13: 0.79166667 | V13: TIME | W13: 0.79166667 | X13: TIME | Y13: 0.79166667 | Z13: TIME | AA13: 0.79166667 | AB13: TIME | AC13: 0.79166667 | AD13: TIME | AE13: 0.79166667 | AF13: TIME | AG13: 0.79166667 | AH13: TIME | AI13: 19:00;00 | AJ13: TIME | AK13: 0.79166667 | AL13: TIME | AM13: 0.79166667 | AN13: TIME | AO13: 0.79166667 | AP13: TIME | AQ13: 0.79166667 | AR13: TIME | AS13: 0.79166667 | AT13: TIME | AU13: 0.79166667 | AV13: TIME | AW13: 0.79166667 | AX13: TIME | AY13: 0.79166667 | AZ13: TIME | BA13: 0.79166667 | BB13: TIME | BC13: 0.79166667 | BD13: TIME | BE13: 0.79166667 | BF13: TIME | BG13: 0.79166667 | BH13: TIME | BI13: 19:00;00 | BJ13: TIME | BK13: 0.79166667 | BL13: TIME | BM13: 0.79166667 | BP13: TIME | BQ13: 0.79166667
A14: SUPERVISOR | C14: DAVID | D14: SUPERVISOR | E14: DAVID | F14: SUPERVISOR | G14: DAVID | H14: SUPERVISOR | I14: DAVID | J14: SUPERVISOR | K14: DAVID | L14: SUPERVISOR | M14: DAVID | N14: SUPERVISOR | O14: DAVID | P14: SUPERVISOR | Q14: DAVID | R14: SUPERVISOR | S14: DAVID | T14: SUPERVISOR | U14: ANNAH | V14: SUPERVISOR | W14: DAVID | X14: SUPERVISOR | Y14: DAVID | Z14: SUPERVISOR | AA14: DAVID | AB14: SUPERVISOR | AC14: DAVID | AD14: SUPERVISOR | AE14: DAVID | AF14: SUPERVISOR | AG14: DAVID | AH14: SUPERVISOR | AI14: DAVID | AJ14: SUPERVISOR | AK14: DAVID | AL14: SUPERVISOR | AM14: DAVID | AN14: SUPERVISOR | AO14: DAVID | AP14: SUPERVISOR | AQ14: DAVID | AR14: SUPERVISOR | AS14: DAVID | AT14: SUPERVISOR | AU14: DAVID | AV14: SUPERVISOR | AW14: DAVID | AX14: SUPERVISOR | AY14: DAVID | AZ14: SUPERVISOR | BA14: ESSIE/Y | BB14: SUPERVISOR | BC14: DAVID | BD14: SUPERVISOR | BE14: DAVID | BF14: SUPERVISOR | BG14: DAVID | BH14: SUPERVISOR | BI14: DAVID | BJ14: SUPERVISOR | BK14: DAVID | BL14: SUPERVISOR | BM14: DAVID | BP14: SUPERVISOR | BQ14: DAVID
A15: CASHIER: | C15: ANNAH | D15: CASHIER | E15: WANDILE | F15: CASHIER | G15: WANDILE | H15: CASHIER | I15: WANDILE | J15: CASHIER | K15: ANNAH | L15: CASHIER | M15: WANDILE | N15: CASHIER | O15: WANDILE | P15: CASHIER | Q15: ANNAH | R15: CASHIER | S15: ANNAH | T15: CASHIER | U15: ANNAH | V15: CASHIER | W15: ANNAH | X15: CASHIER | Y15: WANDILE | Z15: CASHIER | AA15: ANNAH | AB15: CASHIER | AC15: ANNAH | AD15: CASHIER | AE15: ANNAH | AF15: CASHIER | AG15: WANDILE | AH15: CASHIER | AI15: WANDILE | AJ15: CASHIER | AK15: WANDILE | AL15: CASHIER | AM15: ANNAH | AN15: CASHIER | AO15: WANDILE | AP15: CASHIER | AQ15: WANDILE | AR15: CASHIER | AS15: ANNAH/WANDILE | AT15: CASHIER | AU15: ANNAH | AV15: CASHIER | AW15: ANNAH | AX15: CASHIER | AY15: ANNAH | AZ15: CASHIER | BA15: ANNAH | BB15: CASHIER | BC15: ANNAH | BD15: CASHIER | BE15: ANNAH | BF15: CASHIER | BG15: ANNAH | BH15: CASHIER | BI15: WANDILE | BJ15: CASHIER | BK15: WANDILE | BL15: CASHIER | BM15: WANDILE | BP15: CASHIER | BQ15: ANNAH/WANDILE
A16: DISCONTINUE | BP16: DAVID
A17: BONDIBLU HOLES SHELVE | C17: 5 | E17: 5 | G17: 5 | I17: 5 | K17: 5 | M17: 5 | O17: 5 | Q17: 5 | S17: 5 | U17: 5 | W17: 5 | Y17: 5 | AA17: 5 | AC17: 5 | AE17: 5 | AG17: 5 | AI17: 5 | AK17: 5 | AM17: 5 | AO17: 5 | AQ17: 5 | AS17: 5 | AU17: 5 | AW17: 5 | AY17: 6 | BC17: 6 | BE17: 6 | BG17: 6 | BI17: 6 | BK17: 6 | BM17: 6 | BO17: =IF(COUNT(E17,G17,I17,K17,M17,O17,Q17,S17,U17,W17,Y17,AA17,AC17,AE17,AG17,AI17,AK17,AM17,AO17,AQ17,AS17,AU17,AW17,AY17,BA17,BC17,BE17,BG17,BI17,BK17,BM17)=0,"",SUM(E17,G17,I17,K17,M17,O17,Q17,S17,U17,W17,Y17,AA17,AC17,AE17,AG17,AI17,AK17,AM17,AO17,AQ17,AS17,AU17,AW17,AY17,BA17,BC17,BE17,BG17,BI17,BK17,BM17)) -> 157 | BQ17: 0
A18: SUNGLASSES SOLD REPORT | BO18: =IF(COUNT(E18,G18,I18,K18,M18,O18,Q18,S18,U18,W18,Y18,AA18,AC18,AE18,AG18,AI18,AK18,AM18,AO18,AQ18,AS18,AU18,AW18,AY18,BA18,BC18,BE18,BG18,BI18,BK18,BM18)=0,"",SUM(E18,G18,I18,K18,M18,O18,Q18,S18,U18,W18,Y18,AA18,AC18,AE18,AG18,AI18,AK18,AM18,AO18,AQ18,AS18,AU18,AW18,AY18,BA18,BC18,BE18,BG18,BI18,BK18,BM18))
A19: CASH ACC | BO19: =IF(COUNT(E19,G19,I19,K19,M19,O19,Q19,S19,U19,W19,Y19,AA19,AC19,AE19,AG19,AI19,AK19,AM19,AO19,AQ19,AS19,AU19,AW19,AY19,BA19,BC19,BE19,BG19,BI19,BK19,BM19)=0,"",SUM(E19,G19,I19,K19,M19,O19,Q19,S19,U19,W19,Y19,AA19,AC19,AE19,AG19,AI19,AK19,AM19,AO19,AQ19,AS19,AU19,AW19,AY19,BA19,BC19,BE19,BG19,BI19,BK19,BM19))
A20: COINS | BO20: =IF(COUNT(E20,G20,I20,K20,M20,O20,Q20,S20,U20,W20,Y20,AA20,AC20,AE20,AG20,AI20,AK20,AM20,AO20,AQ20,AS20,AU20,AW20,AY20,BA20,BC20,BE20,BG20,BI20,BK20,BM20)=0,"",SUM(E20,G20,I20,K20,M20,O20,Q20,S20,U20,W20,Y20,AA20,AC20,AE20,AG20,AI20,AK20,AM20,AO20,AQ20,AS20,AU20,AW20,AY20,BA20,BC20,BE20,BG20,BI20,BK20,BM20))
A21: SAFEDROPS | C21: =620+1500+1180+1700+1400+1300+2600+1100+1500+1600 -> 14500 | E21: =140+450+1300+1200+1100+2000+1550+1650+1200+1200 -> 11790 | G21: =110+850+1300+2200+1300+1800+1700+1400+1300 -> 11960 | I21: =310+1100+1000+950+1200+1400+1100+1650+1400+1500+2200+1000+1900 -> 16710 | K21: =1550+2210+2100+1700+1500+1850 -> 10910 | M21: =180+500+600+1400+2150+1200+1500+1100+1400+1500+1400+2100+100 -> 15130 | O21: =540+1200+1350+950+700+1000+1600+1200+1300+1100 -> 10940 | Q21: =860+1650+2000+3150+1500+3600 -> 12760 | S21: =1800+3150+2900+1500+1900+2500+1580 -> 15330 | U21: =2750+1550+200+70+1200+1950+1700 -> 9420 | W21: =1600+2250+1700+3250+2100+2050+440 -> 13390 | Y21: =30+840+1400+1300+1500+1400+700+1400+1050+2000+1600 -> 13220 | AA21: =300+400+3200+2350+1450+1850+2800 -> 12350 | AC21: =1400+1400+2500+190+2800+2560+2950 -> 13800 | AE21: =80+900+1800+2400+2350+1500+1500 -> 10530 | AG21: =190+670+1300+2000+1000+1100+1300+1600+1000+900+1700+800 -> 13560 | AI21: =890+700+1100+1300+1900+1100+1100+1000+1300 -> 10390 | AK21: =350+950+900+1200+1450+200+1600+1300+1200+3300+20+1200+1400+900+1600 -> 17570 | AM21: =1400+2150+1400+1900+1600+10+10+3100+1800+1600 -> 14970 | AN21: =-360-1020-1500-1950-1100-1400-1000-1100-1600-1700 -> -12730 | AO21: =360+1020+1500+1950+1100+1400+1000+1100+1600+1700 -> 12730 | AP21: =-110-1490-530-900-1100-150-1200-800-1500-1300-1000-1200-1800 -> -13080 | AQ21: =110+1490+530+900+1100+150+1200+800+1500+1200+1000+1300+1800 -> 13080 | AR21: =-540-3600-100-2180-1700-1300-1100 -> -10520 | AS21: =540+3600+100+2180+1700+1300+1100 -> 10520 | AT21: =-2900-1800-1650-1450-1900-1800-2000-1800 -> -15300 | AU21: =1800+2900+2000+1800+1900+1450+1650+1800 -> 15300 | AV21: =-400-590-1500-2650-2150-1450-3400-2050 -> -14190 | AW21: =400+590+1500+2650+1450+2150+3400+2050 -> 14190 | AX21: =-1800-1700-1550-120-800-2000 -> -7970 | AY21: =1800+1700+1550+120+800+2000 -> 7970 | BA21: =80+490+1350+1400+1300+1300+1200+1100+1800+1100 -> 11120 | BC21: =270+1800+1300+1700+1800+870 -> 7740 | BE21: =690+2000+1300+1800+2400+1950+2150+1230+1450 -> 14970 | BG21: =660+1600+2900+2000+1400+2000+3310+2500+2200 -> 18570 | BI21: =1410+760+1100+1500+1200+1700+1650+2800+2700+1200+2100 -> 18120 | BK21: =190+700+1400+1300+1000+1100+1000+1700+1400+1200+1400 -> 12390 | BM21: =520+900+580+2200+1200+1300+2000+900+1300+1250+1600+1700 -> 15450 | BO21: =IF(COUNT(E21,G21,I21,K21,M21,O21,Q21,S21,U21,W21,Y21,AA21,AC21,AE21,AG21,AI21,AK21,AM21,AO21,AQ21,AS21,AU21,AW21,AY21,BA21,BC21,BE21,BG21,BI21,BK21,BM21)=0,"",SUM(E21,G21,I21,K21,M21,O21,Q21,S21,U21,W21,Y21,AA21,AC21,AE21,AG21,AI21,AK21,AM21,AO21,AQ21,AS21,AU21,AW21,AY21,BA21,BC21,BE21,BG21,BI21,BK21,BM21)) -> 406880 | BQ21: =1600+2300+1800+1400+1800+1600+1800+1150+980+250+1100 -> 15780
A22: CASH | C22: =SUM(C20:C21) -> 14500 | E22: =SUM(E20:E21) -> 11790 | G22: =SUM(G20:G21) -> 11960 | I22: =SUM(I20:I21) -> 16710 | K22: =SUM(K20:K21) -> 10910 | M22: =SUM(M20:M21) -> 15130 | O22: =SUM(O20:O21) -> 10940 | Q22: =SUM(Q20:Q21) -> 12760 | S22: =SUM(S20:S21) -> 15330 | U22: =SUM(U20:U21) -> 9420 | W22: =SUM(W20:W21) -> 13390 | Y22: =SUM(Y20:Y21) -> 13220 | AA22: =SUM(AA20:AA21) -> 12350 | AC22: =SUM(AC20:AC21) -> 13800 | AE22: =SUM(AE20:AE21) -> 10530 | AG22: =SUM(AG20:AG21) -> 13560 | AI22: =SUM(AI20:AI21) -> 10390 | AK22: =SUM(AK20:AK21) -> 17570 | AM22: =SUM(AM20:AM21) -> 14970 | AO22: =SUM(AO20:AO21) -> 12730 | AQ22: =SUM(AQ20:AQ21) -> 13080 | AS22: =SUM(AS20:AS21) -> 10520 | AU22: =SUM(AU20:AU21) -> 15300 | AW22: =SUM(AW20:AW21) -> 14190 | AY22: =SUM(AY20:AY21) -> 7970 | BA22: =SUM(BA20:BA21) -> 11120 | BC22: =SUM(BC20:BC21) -> 7740 | BE22: =SUM(BE20:BE21) -> 14970 | BG22: =SUM(BG20:BG21) -> 18570 | BI22: =SUM(BI20:BI21) -> 18120 | BK22: =SUM(BK20:BK21) -> 12390 | BM22: =SUM(BM20:BM21) -> 15450 | BO22: =IF(COUNT(E22,G22,I22,K22,M22,O22,Q22,S22,U22,W22,Y22,AA22,AC22,AE22,AG22,AI22,AK22,AM22,AO22,AQ22,AS22,AU22,AW22,AY22,BA22,BC22,BE22,BG22,BI22,BK22,BM22)=0,"",SUM(E22,G22,I22,K22,M22,O22,Q22,S22,U22,W22,Y22,AA22,AC22,AE22,AG22,AI22,AK22,AM22,AO22,AQ22,AS22,AU22,AW22,AY22,BA22,BC22,BE22,BG22,BI22,BK22,BM22)) -> 406880 | BQ22: =SUM(BQ20:BQ21) -> 15780
A23: VOUCHERS | BO23: =IF(COUNT(E23,G23,I23,K23,M23,O23,Q23,S23,U23,W23,Y23,AA23,AC23,AE23,AG23,AI23,AK23,AM23,AO23,AQ23,AS23,AU23,AW23,AY23,BA23,BC23,BE23,BG23,BI23,BK23,BM23)=0,"",SUM(E23,G23,I23,K23,M23,O23,Q23,S23,U23,W23,Y23,AA23,AC23,AE23,AG23,AI23,AK23,AM23,AO23,AQ23,AS23,AU23,AW23,AY23,BA23,BC23,BE23,BG23,BI23,BK23,BM23))
A24: coins banked (in minus) | BO24: =IF(COUNT(E24,G24,I24,K24,M24,O24,Q24,S24,U24,W24,Y24,AA24,AC24,AE24,AG24,AI24,AK24,AM24,AO24,AQ24,AS24,AU24,AW24,AY24,BA24,BC24,BE24,BG24,BI24,BK24,BM24)=0,"",SUM(E24,G24,I24,K24,M24,O24,Q24,S24,U24,W24,Y24,AA24,AC24,AE24,AG24,AI24,AK24,AM24,AO24,AQ24,AS24,AU24,AW24,AY24,BA24,BC24,BE24,BG24,BI24,BK24,BM24))
A25: AIRTIME SLIP | C25: 2654 | E25: 2667 | G25: 2042 | I25: 1745 | K25: 1859 | M25: 2273 | O25: 3017 | Q25: 1754 | S25: 1544 | U25: 1765 | W25: 1538 | Y25: 1826 | AA25: 1619 | AC25: 1813 | AE25: 1871 | AG25: 1912 | AI25: 1147 | AK25: 1973 | AM25: 1489 | AO25: 1302 | AQ25: 1685 | AS25: 2535 | AU25: 1760 | AW25: 2052 | AY25: 1797 | BA25: 881 | BC25: 1717 | BE25: 2138 | BG25: 1990 | BI25: 2075 | BK25: 1921 | BM25: 3986 | BO25: =IF(COUNT(E25,G25,I25,K25,M25,O25,Q25,S25,U25,W25,Y25,AA25,AC25,AE25,AG25,AI25,AK25,AM25,AO25,AQ25,AS25,AU25,AW25,AY25,BA25,BC25,BE25,BG25,BI25,BK25,BM25)=0,"",SUM(E25,G25,I25,K25,M25,O25,Q25,S25,U25,W25,Y25,AA25,AC25,AE25,AG25,AI25,AK25,AM25,AO25,AQ25,AS25,AU25,AW25,AY25,BA25,BC25,BE25,BG25,BI25,BK25,BM25)) -> 59693 | BQ25: 1114
A26: AIRTIME SYSTEM | C26: 2254 | E26: 2667 | G26: 2046 | I26: 1745 | K26: 1859 | M26: 2283 | O26: 3017 | Q26: 1754 | S26: 1544 | U26: 1765 | W26: 1538 | Y26: 1826 | AA26: 1619 | AC26: 1813 | AE26: 1871 | AG26: 1912 | AI26: 1147 | AK26: 1973 | AM26: 1489 | AO26: 1302 | AQ26: 1655 | AS26: 2535 | AU26: 1760 | AW26: 2052 | AY26: 1797 | BA26: 881 | BC26: 1717 | BE26: 2138 | BG26: 1910 | BI26: 2075 | BK26: 1921 | BM26: 3986 | BO26: =IF(COUNT(E26,G26,I26,K26,M26,O26,Q26,S26,U26,W26,Y26,AA26,AC26,AE26,AG26,AI26,AK26,AM26,AO26,AQ26,AS26,AU26,AW26,AY26,BA26,BC26,BE26,BG26,BI26,BK26,BM26)=0,"",SUM(E26,G26,I26,K26,M26,O26,Q26,S26,U26,W26,Y26,AA26,AC26,AE26,AG26,AI26,AK26,AM26,AO26,AQ26,AS26,AU26,AW26,AY26,BA26,BC26,BE26,BG26,BI26,BK26,BM26)) -> 59597 | BQ26: 1114
A27: AIRTME SHIFT NR | C27: 84 | E27: 85 | G27: 86 | I27: 87 | K27: 88 | M27: 89 | O27: 90 | Q27: 91 | S27: 92 | U27: 93 | W27: 94 | Y27: 95 | AA27: 96 | AC27: 97 | AE27: 98 | AG27: 99 | AI27: 100 | AK27: 101 | AM27: 102 | AO27: 103 | AQ27: 104 | AS27: 105 | AU27: 106 | AW27: 107 | AY27: 108 | BA27: 109 | BC27: 110 | BE27: 111 | BG27: 112 | BI27: 113 | BK27: 114 | BM27: 115 | BO27: =IF(COUNT(E27,G27,I27,K27,M27,O27,Q27,S27,U27,W27,Y27,AA27,AC27,AE27,AG27,AI27,AK27,AM27,AO27,AQ27,AS27,AU27,AW27,AY27,BA27,BC27,BE27,BG27,BI27,BK27,BM27)=0,"",SUM(E27,G27,I27,K27,M27,O27,Q27,S27,U27,W27,Y27,AA27,AC27,AE27,AG27,AI27,AK27,AM27,AO27,AQ27,AS27,AU27,AW27,AY27,BA27,BC27,BE27,BG27,BI27,BK27,BM27)) -> 3100 | BQ27: 116
A28: AIRTIME BALANCE | C28: 3890.93 | E28: 6305.67 | G28: 4330.72 | I28: 2644.63 | K28: 5844.24 | M28: 3645 | O28: 5728.66 | Q28: 6034.83 | S28: 4539.9 | U28: 1765 | W28: 1339.91 | Y28: 4568.67 | AA28: 3004.31 | AC28: 1250 | AE28: 4441.1 | AG28: 2587.04 | AI28: 1478.92 | AK28: 4569.8 | AM28: 3128.65 | AO28: 6867.16 | AQ28: 5237.02 | AS28: 9783.15 | AU28: 8081.21 | AW28: 6096 | AY28: 9357.19 | BA28: 8504.46 | BC28: 6844.01 | BE28: 4771.13 | BG28: 9846.84 | BI28: 7837.91 | BK28: 5978.79 | BM28: 2116.24 | BO28: =IF(COUNT(E28,G28,I28,K28,M28,O28,Q28,S28,U28,W28,Y28,AA28,AC28,AE28,AG28,AI28,AK28,AM28,AO28,AQ28,AS28,AU28,AW28,AY28,BA28,BC28,BE28,BG28,BI28,BK28,BM28)=0,"",SUM(E28,G28,I28,K28,M28,O28,Q28,S28,U28,W28,Y28,AA28,AC28,AE28,AG28,AI28,AK28,AM28,AO28,AQ28,AS28,AU28,AW28,AY28,BA28,BC28,BE28,BG28,BI28,BK28,BM28)) -> 158528.16 | BQ28: 6039.18
A29: AIRTIME LOADED | Q29: 2000 | W29: 5000 | AE29: 5000 | AK29: 5000 | AO29: 5000 | AS29: 7000 | AY29: 5000 | BG29: 7000 | BO29: =IF(COUNT(E29,G29,I29,K29,M29,O29,Q29,S29,U29,W29,Y29,AA29,AC29,AE29,AG29,AI29,AK29,AM29,AO29,AQ29,AS29,AU29,AW29,AY29,BA29,BC29,BE29,BG29,BI29,BK29,BM29)=0,"",SUM(E29,G29,I29,K29,M29,O29,Q29,S29,U29,W29,Y29,AA29,AC29,AE29,AG29,AI29,AK29,AM29,AO29,AQ29,AS29,AU29,AW29,AY29,BA29,BC29,BE29,BG29,BI29,BK29,BM29)) -> 41000 | BQ29: 5000
E30: =E28-(C28-E25+E29) -> 5081.74 | G30: =G28-(E28-G25+G29) -> 67.05 | I30: =I28-(G28-I25+I29) -> 58.91 | K30: =K28-(I28-K25+K29) -> 5058.61 | M30: =M28-(K28-M25+M29) -> 73.76 | O30: =O28-(M28-O25+O29) -> 5100.66 | Q30: =Q28-(O28-Q25+Q29) -> 60.17 | S30: =S28-(Q28-S25+S29) -> 49.07 | U30: =U28-(S28-U25+U29) -> -1009.9 | W30: =W28-(U28-W25+W29) -> -3887.09 | Y30: =Y28-(W28-Y25+Y29) -> 5054.76 | AA30: =AA28-(Y28-AA25+AA29) -> 54.64 | AC30: =AC28-(AA28-AC25+AC29) -> 58.69 | AE30: =AE28-(AC28-AE25+AE29) -> 62.1 | AG30: =AG28-(AE28-AG25+AG29) -> 57.94 | AI30: =AI28-(AG28-AI25+AI29) -> 38.88 | AK30: =AK28-(AI28-AK25+AK29) -> 63.88 | AM30: =AM28-(AK28-AM25+AM29) -> 47.85 | AO30: =AO28-(AM28-AO25+AO29) -> 40.51 | AQ30: =AQ28-(AO28-AQ25+AQ29) -> 54.86 | AS30: =AS28-(AQ28-AS25+AS29) -> 81.13 | AU30: =AU28-(AS28-AU25+AU29) -> 58.06 | AW30: =AW28-(AU28-AW25+AW29) -> 66.79 | AY30: =AY28-(AW28-AY25+AY29) -> 58.19 | BA30: =BA28-(AY28-BA25+BA29) -> 28.27 | BC30: =BC28-(BA28-BC25+BC29) -> 56.55 | BE30: =BE28-(BC28-BE25+BE29) -> 65.12 | BG30: =BG28-(BE28-BG25+BG29) -> 65.71 | BI30: =BI28-(BG28-BI25+BI29) -> 66.07 | BK30: =BK28-(BI28-BK25+BK29) -> 61.88 | BM30: =BM28-(BK28-BM25+BM29) -> 123.45 | BO30: =IF(COUNT(E30,G30,I30,K30,M30,O30,Q30,S30,U30,W30,Y30,AA30,AC30,AE30,AG30,AI30,AK30,AM30,AO30,AQ30,AS30,AU30,AW30,AY30,BA30,BC30,BE30,BG30,BI30,BK30,BM30)=0,"",SUM(E30,G30,I30,K30,M30,O30,Q30,S30,U30,W30,Y30,AA30,AC30,AE30,AG30,AI30,AK30,AM30,AO30,AQ30,AS30,AU30,AW30,AY30,BA30,BC30,BE30,BG30,BI30,BK30,BM30)) -> 16918.31 | BQ30: =BQ28-(BM28-BQ25+BQ29) -> 36.94
E31: =IF(E25=0,"",E30/E25*100) -> 190.54143 | G31: =IF(G25=0,"",G30/G25*100) -> 3.2835455 | I31: =IF(I25=0,"",I30/I25*100) -> 3.3759312 | K31: =IF(K25=0,"",K30/K25*100) -> 272.11458 | M31: =IF(M25=0,"",M30/M25*100) -> 3.2450506 | O31: =IF(O25=0,"",O30/O25*100) -> 169.06397 | Q31: =IF(Q25=0,"",Q30/Q25*100) -> 3.4304447 | S31: =IF(S25=0,"",S30/S25*100) -> 3.1781088 | U31: =IF(U25=0,"",U30/U25*100) -> -57.21813 | W31: =IF(W25=0,"",W30/W25*100) -> -252.73667 | Y31: =IF(Y25=0,"",Y30/Y25*100) -> 276.82147 | AA31: =IF(AA25=0,"",AA30/AA25*100) -> 3.3749228 | AC31: =IF(AC25=0,"",AC30/AC25*100) -> 3.237176 | AE31: =IF(AE25=0,"",AE30/AE25*100) -> 3.3190807 | AG31: =IF(AG25=0,"",AG30/AG25*100) -> 3.0303347 | AI31: =IF(AI25=0,"",AI30/AI25*100) -> 3.3897123 | AK31: =IF(AK25=0,"",AK30/AK25*100) -> 3.2377091 | AM31: =IF(AM25=0,"",AM30/AM25*100) -> 3.2135662 | AO31: =IF(AO25=0,"",AO30/AO25*100) -> 3.1113671 | AQ31: =IF(AQ25=0,"",AQ30/AQ25*100) -> 3.2557864 | AS31: =IF(AS25=0,"",AS30/AS25*100) -> 3.2003945 | AU31: =IF(AU25=0,"",AU30/AU25*100) -> 3.2988636 | AW31: =IF(AW25=0,"",AW30/AW25*100) -> 3.2548733 | AY31: =IF(AY25=0,"",AY30/AY25*100) -> 3.2381747 | BA31: =IF(BA25=0,"",BA30/BA25*100) -> 3.2088536 | BC31: =IF(BC25=0,"",BC30/BC25*100) -> 3.2935352 | BE31: =IF(BE25=0,"",BE30/BE25*100) -> 3.0458372 | BG31: =IF(BG25=0,"",BG30/BG25*100) -> 3.3020101 | BI31: =IF(BI25=0,"",BI30/BI25*100) -> 3.1840964 | BK31: =IF(BK25=0,"",BK30/BK25*100) -> 3.2212389 | BM31: =IF(BM25=0,"",BM30/BM25*100) -> 3.0970898 | BO31: =IF(COUNT(E31,G31,I31,K31,M31,O31,Q31,S31,U31,W31,Y31,AA31,AC31,AE31,AG31,AI31,AK31,AM31,AO31,AQ31,AS31,AU31,AW31,AY31,BA31,BC31,BE31,BG31,BI31,BK31,BM31)=0,"",SUM(E31,G31,I31,K31,M31,O31,Q31,S31,U31,W31,Y31,AA31,AC31,AE31,AG31,AI31,AK31,AM31,AO31,AQ31,AS31,AU31,AW31,AY31,BA31,BC31,BE31,BG31,BI31,BK31,BM31)) -> 679.61435 | BQ31: =IF(BQ25=0,"",BQ30/BQ25*100) -> 3.3159785
A32: ACCOUNT | C32: =161.5+25+15 -> 201.5 | E32: 15 | G32: 15 | I32: 243.9 | K32: =15+215.9 -> 230.9 | M32: =58.32+161.4 -> 219.72 | O32: =15+22+22 -> 59 | Q32: =44+3.5+51.5 -> 99 | S32: =25+15+1849.93 -> 1889.93 | U32: =22+49.5 -> 71.5 | W32: 2 | Y32: =22+15+80+189.9+15+1417.5+15+24 -> 1778.4 | AA32: =165.4+25+44+124.5 -> 358.9 | AC32: =37+89.5+15 -> 141.5 | AE32: =4+22 -> 26 | AG32: 15 | AI32: 22 | AK32: =127.9+22+60.8 -> 210.7 | AM32: =37+22+33.9 -> 92.9 | AO32: =73.8+19.5+37 -> 130.3 | AQ32: 33.9 | AS32: =133+106.58+34.5+55.9 -> 329.98 | AU32: 189.9 | AW32: 25.5 | AY32: =22+15 -> 37 | BA32: 39.9 | BC32: =22+2+138+23.9+55.9 -> 241.8 | BE32: 1955.85 | BG32: =1297.32+15+22 -> 1334.32 | BI32: =19.5+22+37 -> 78.5 | BK32: 24 | BM32: =15+126.9+22 -> 163.9 | BO32: =IF(COUNT(E32,G32,I32,K32,M32,O32,Q32,S32,U32,W32,Y32,AA32,AC32,AE32,AG32,AI32,AK32,AM32,AO32,AQ32,AS32,AU32,AW32,AY32,BA32,BC32,BE32,BG32,BI32,BK32,BM32)=0,"",SUM(E32,G32,I32,K32,M32,O32,Q32,S32,U32,W32,Y32,AA32,AC32,AE32,AG32,AI32,AK32,AM32,AO32,AQ32,AS32,AU32,AW32,AY32,BA32,BC32,BE32,BG32,BI32,BK32,BM32)) -> 10076.2 | BQ32: =15+43.8+22+33.9+33.9+33.9+33.9 -> 216.4
A33: R/ACCOUNT | C33: =2035.9+500.09+114.99+8773.52+72.9+2538.8+1611.5+378.12 -> 16025.82 | BM33: =2311.1+764+1955.85+187.7 -> 5218.65 | BO33: =IF(COUNT(E33,G33,I33,K33,M33,O33,Q33,S33,U33,W33,Y33,AA33,AC33,AE33,AG33,AI33,AK33,AM33,AO33,AQ33,AS33,AU33,AW33,AY33,BA33,BC33,BE33,BG33,BI33,BK33,BM33)=0,"",SUM(E33,G33,I33,K33,M33,O33,Q33,S33,U33,W33,Y33,AA33,AC33,AE33,AG33,AI33,AK33,AM33,AO33,AQ33,AS33,AU33,AW33,AY33,BA33,BC33,BE33,BG33,BI33,BK33,BM33)) -> 5218.65
A34: PAYOUTS | C34: =541.27+238.5+70+460+2035.9+2347.8+71+228+205.9+127.5+63.5+72.9+1053.6+22+31+740+300 -> 8608.87 | E34: =300+48+20+180 -> 548 | G34: 1000 | I34: =300+1250.2+192+189.2+300 -> 2231.4 | K34: =215.24+215.24+299+300+272+345+640.8+300 -> 2587.28 | M34: =300+452.4+458.8 -> 1211.2 | O34: =300+760+280+160 -> 1500 | Q34: =119.9+300+300+378.4+234 -> 1332.3 | S34: =481.24+120+300+300+160+350.4 -> 1711.64 | U34: =300+300 -> 600 | W34: =300+300+399.26 -> 999.26 | Y34: =300+80+144 -> 524 | AA34: =150+460+518.4+192+752.8 -> 2073.2 | AC34: =600+300+80+242.4+144+448.4 -> 1814.8 | AE34: =300+300+1030.38+128+2462.48+105+600+420+390 -> 5735.86 | AG34: =80+500+158.4 -> 738.4 | AK34: =300+300+21.9+21.9+119.2+272 -> 1035 | AM34: =300+300+40+180+80 -> 900 | AN34: =-428-300-161.6-399.2-262 -> -1550.8 | AO34: =428+300+161.6+262+399.2 -> 1550.8 | AP34: =-300-844.15-80-1221.3 -> -2445.45 | AQ34: =300+844.15+80+1221.3 -> 2445.45 | AR34: =-300-300-721.39-578-192-345 -> -2436.39 | AS34: =721.39+300+300+345+578+192 -> 2436.39 | AT34: =-300-300-370-144-259.2-160 -> -1533.2 | AU34: =300+300+370+144+259.2+160 -> 1533.2 | AV34: =-272-139.9-300-300 -> -1011.9 | AW34: =300+300+272+139.9 -> 1011.9 | AX34: =-300-300-35-99-98-262 -> -1094 | AY34: =35+300+300+99+98+262 -> 1094 | BA34: =329.2+160+300+330+336+253.48 -> 1708.68 | BC34: =388.8+344+460+1167+300 -> 2659.8 | BE34: =700+600+300+80 -> 1680 | BG34: =345.19+741.4+300+300+150+390+140+196 -> 2562.59 | BI34: =272+80 -> 352 | BK34: 272 | BM34: =300+300+518.5+360+187.7+1955.85+764+2311.1+35.5 -> 6732.65 | BO34: =IF(COUNT(E34,G34,I34,K34,M34,O34,Q34,S34,U34,W34,Y34,AA34,AC34,AE34,AG34,AI34,AK34,AM34,AO34,AQ34,AS34,AU34,AW34,AY34,BA34,BC34,BE34,BG34,BI34,BK34,BM34)=0,"",SUM(E34,G34,I34,K34,M34,O34,Q34,S34,U34,W34,Y34,AA34,AC34,AE34,AG34,AI34,AK34,AM34,AO34,AQ34,AS34,AU34,AW34,AY34,BA34,BC34,BE34,BG34,BI34,BK34,BM34)) -> 52581.8 | BQ34: =300+300+518+35.5+535.5+80+876 -> 2645
BO35: =IF(COUNT(E35,G35,I35,K35,M35,O35,Q35,S35,U35,W35,Y35,AA35,AC35,AE35,AG35,AI35,AK35,AM35,AO35,AQ35,AS35,AU35,AW35,AY35,BA35,BC35,BE35,BG35,BI35,BK35,BM35)=0,"",SUM(E35,G35,I35,K35,M35,O35,Q35,S35,U35,W35,Y35,AA35,AC35,AE35,AG35,AI35,AK35,AM35,AO35,AQ35,AS35,AU35,AW35,AY35,BA35,BC35,BE35,BG35,BI35,BK35,BM35))
A36: S/P 20231005 | B36: M1980697 | C36: 9180.65 | D36: 542 | E36: 7104 | F36: 543 | G36: 1492.7 | H36: 544&5 | I36: =1000+3515.8 -> 4515.8 | J36: 546 | K36: 9936.75 | L36: 547 | M36: 8598.3 | N36: 548&9 | O36: =1896.25+7485.45 -> 9381.7 | P36: 550 | Q36: 7129.85 | R36: 551 | S36: 72.5 | T36: 552 | U36: 2642.55 | V36: 553 | W36: 971.25 | X36: 554 | Y36: 9066.45 | Z36: 555&6 | AA36: =845.4+9395.05 -> 10240.45 | AB36: 557 | AC36: 8460.95 | AD36: 558&9 | AE36: =1456.45+2246.45 -> 3702.9 | AF36: 560&1 | AG36: =1899.15+4514.9 -> 6414.05 | AH36: 562 | AI36: 800 | AJ36: 563 | AK36: 7147.65 | AL36: 564 | AM36: 5161.5 | AN36: 565 | AO36: 7571.55 | AP36: 566 | AQ36: 4805.7 | AR36: 567 | AS36: 6264.35 | AT36: 568 | AU36: 4100.1 | AV36: 569 | AW36: 1266.9 | AX36: 570 | AY36: 7215.4 | AZ36: 571 | BA36: 4651.9 | BB36: 572 | BC36: 2332.15 | BD36: 573 | BE36: 4516.25 | BF36: 574 | BG36: 4466.85 | BH36: 575 | BI36: 1016.8 | BJ36: 576 | BK36: 3838 | BL36: 577 | BM36: 983.3 | BO36: =IF(COUNT(E36,G36,I36,K36,M36,O36,Q36,S36,U36,W36,Y36,AA36,AC36,AE36,AG36,AI36,AK36,AM36,AO36,AQ36,AS36,AU36,AW36,AY36,BA36,BC36,BE36,BG36,BI36,BK36,BM36)=0,"",SUM(E36,G36,I36,K36,M36,O36,Q36,S36,U36,W36,Y36,AA36,AC36,AE36,AG36,AI36,AK36,AM36,AO36,AQ36,AS36,AU36,AW36,AY36,BA36,BC36,BE36,BG36,BI36,BK36,BM36)) -> 155868.6 | BP36: 578 | BQ36: 7444.65
BO37: =IF(COUNT(E37,G37,I37,K37,M37,O37,Q37,S37,U37,W37,Y37,AA37,AC37,AE37,AG37,AI37,AK37,AM37,AO37,AQ37,AS37,AU37,AW37,AY37,BA37,BC37,BE37,BG37,BI37,BK37,BM37)=0,"",SUM(E37,G37,I37,K37,M37,O37,Q37,S37,U37,W37,Y37,AA37,AC37,AE37,AG37,AI37,AK37,AM37,AO37,AQ37,AS37,AU37,AW37,AY37,BA37,BC37,BE37,BG37,BI37,BK37,BM37))
A38: S/P 5151816 | B38: M3461399 | C38: 14307.75 | D38: 147 | E38: 15062.7 | F38: 148 | G38: 8874.7 | H38: 149 | I38: 20021.5 | J38: 150 | K38: 21011.45 | L38: 151 | M38: 12727.45 | N38: 152 | O38: 14080.65 | P38: 153 | Q38: 13494.9 | R38: 154 | S38: =1330.4+200+200+150+2000+500+805.3+400+428.1+300+300+680.1+300+300+200+400+100+800+150+700+300+1000+200+606.1+700+400+350+200+1539.95+400+100+300 -> 16339.95 | T38: 155&6 | U38: =1+5142.15 -> 5143.15 | V38: 157 | W38: 6480.6 | X38: 158 | Y38: 13417 | Z38: 159 | AA38: 17994.65 | AB38: 160 | AC38: 16604.7 | AD38: 161 | AE38: 22991.35 | AF38: 162 | AG38: 15296.54 | AH38: 163 | AI38: 18272.4 | AJ38: 164 | AK38: 22982.05 | AL38: 165 | AM38: 12498.95 | AN38: 166 | AO38: 13115.75 | AP38: 167 | AQ38: 7750.6 | AR38: 168 | AS38: 12970.15 | AT38: 169 | AU38: 10630.8 | AV38: 170 | AW38: 9283.95 | AX38: 171 | AY38: 12321 | AZ38: 172 | BA38: 13351.55 | BB38: 173 | BC38: 17017 | BD38: 174 | BE38: 27304.65 | BF38: 175 | BG38: 22084.6 | BH38: 176 | BI38: 17179.05 | BJ38: 177 | BK38: 13565.45 | BL38: 178 | BM38: 22542 | BO38: =IF(COUNT(E38,G38,I38,K38,M38,O38,Q38,S38,U38,W38,Y38,AA38,AC38,AE38,AG38,AI38,AK38,AM38,AO38,AQ38,AS38,AU38,AW38,AY38,BA38,BC38,BE38,BG38,BI38,BK38,BM38)=0,"",SUM(E38,G38,I38,K38,M38,O38,Q38,S38,U38,W38,Y38,AA38,AC38,AE38,AG38,AI38,AK38,AM38,AO38,AQ38,AS38,AU38,AW38,AY38,BA38,BC38,BE38,BG38,BI38,BK38,BM38)) -> 472411.24 | BP38: 179&180&1 | BQ38: =11111.95+32127.55+53745.6 -> 96985.1
A39: S/P 5151341 | B39: M3461399 | C39: 18119.85 | D39: 76 | E39: 17493.1 | F39: 77 | G39: 7481.85 | H39: 78 | I39: 19020.95 | J39: 79 | K39: 13603.2 | L39: 80 | M39: 16706.8 | N39: 81 | O39: 10273.5 | P39: 82 | Q39: 18601.95 | R39: 83 | S39: 12823.65 | T39: 84 | U39: 15822.95 | V39: 85 | W39: 20614.35 | X39: 86 | Y39: 17452.7 | Z39: 87 | AA39: 5069.55 | AB39: 88 | AC39: 11745.55 | AD39: 89 | AE39: 17156.7 | AF39: 90 | AG39: 7208.85 | AJ39: 91 | AK39: 7206.4 | AL39: 92 | AM39: 14419.75 | AN39: 93 | AO39: 12000.8 | AP39: 94 | AQ39: 17545.05 | AR39: 95 | AS39: 22071.9 | AT39: 96 | AU39: 12501.25 | AV39: 97 | AW39: 5180.65 | AX39: 98 | AY39: 12008.55 | AZ39: 99 | BA39: 26594.15 | BB39: 100 | BC39: 10789.15 | BD39: 101 | BE39: 11882.7 | BF39: 102 | BG39: 20625.15 | BH39: 103 | BI39: 14877.85 | BJ39: 104 | BK39: 7409.75 | BL39: 105 | BM39: 24381.25 | BO39: =IF(COUNT(E39,G39,I39,K39,M39,O39,Q39,S39,U39,W39,Y39,AA39,AC39,AE39,AG39,AI39,AK39,AM39,AO39,AQ39,AS39,AU39,AW39,AY39,BA39,BC39,BE39,BG39,BI39,BK39,BM39)=0,"",SUM(E39,G39,I39,K39,M39,O39,Q39,S39,U39,W39,Y39,AA39,AC39,AE39,AG39,AI39,AK39,AM39,AO39,AQ39,AS39,AU39,AW39,AY39,BA39,BC39,BE39,BG39,BI39,BK39,BM39)) -> 430570 | BP39: 106 | BQ39: 36364.83
